Exception on / [GET]
Traceback (most recent call last):
  File "C:\Users\mrend\Desktop\mysite\venv\lib\site-packages\flask\app.py", line 2446, in wsgi_app
    response = self.full_dispatch_request()
  File "C:\Users\mrend\Desktop\mysite\venv\lib\site-packages\flask\app.py", line 1951, in full_dispatch_request
    rv = self.handle_user_exception(e)
  File "C:\Users\mrend\Desktop\mysite\venv\lib\site-packages\flask\app.py", line 1820, in handle_user_exception
    reraise(exc_type, exc_value, tb)
  File "C:\Users\mrend\Desktop\mysite\venv\lib\site-packages\flask\_compat.py", line 39, in reraise
    raise value
  File "C:\Users\mrend\Desktop\mysite\venv\lib\site-packages\flask\app.py", line 1949, in full_dispatch_request
    rv = self.dispatch_request()
  File "C:\Users\mrend\Desktop\mysite\venv\lib\site-packages\flask\app.py", line 1935, in dispatch_request
    return self.view_functions[rule.endpoint](**req.view_args)
  File "C:\Users\mrend\Desktop\mysite\app\routes\index.py", line 13, in index
    cur = mysql.connection.cursor()
  File "C:\Users\mrend\Desktop\mysite\venv\lib\site-packages\flask_mysqldb\__init__.py", line 94, in connection
    ctx.mysql_db = self.connect
  File "C:\Users\mrend\Desktop\mysite\venv\lib\site-packages\flask_mysqldb\__init__.py", line 81, in connect
    return MySQLdb.connect(**kwargs)
  File "C:\Users\mrend\Desktop\mysite\venv\lib\site-packages\MySQLdb\__init__.py", line 84, in Connect
    return Connection(*args, **kwargs)
  File "C:\Users\mrend\Desktop\mysite\venv\lib\site-packages\MySQLdb\connections.py", line 179, in __init__
    super(Connection, self).__init__(*args, **kwargs2)
MySQLdb._exceptions.OperationalError: (2003, "Can't connect to MySQL server on 'localhost' (10061)")
Exception on /dodajwpis [POST]
Traceback (most recent call last):
  File "C:\Users\mrend\Desktop\mysite\venv\lib\site-packages\flask\app.py", line 2446, in wsgi_app
    response = self.full_dispatch_request()
  File "C:\Users\mrend\Desktop\mysite\venv\lib\site-packages\flask\app.py", line 1951, in full_dispatch_request
    rv = self.handle_user_exception(e)
  File "C:\Users\mrend\Desktop\mysite\venv\lib\site-packages\flask\app.py", line 1820, in handle_user_exception
    reraise(exc_type, exc_value, tb)
  File "C:\Users\mrend\Desktop\mysite\venv\lib\site-packages\flask\_compat.py", line 39, in reraise
    raise value
  File "C:\Users\mrend\Desktop\mysite\venv\lib\site-packages\flask\app.py", line 1949, in full_dispatch_request
    rv = self.dispatch_request()
  File "C:\Users\mrend\Desktop\mysite\venv\lib\site-packages\flask\app.py", line 1935, in dispatch_request
    return self.view_functions[rule.endpoint](**req.view_args)
  File "C:\Users\mrend\Desktop\mysite\app\routes\add_post.py", line 58, in add_post
    file.save(os.path.join('app/static/images/', post_id + imageAttached))
TypeError: unsupported operand type(s) for +: 'int' and 'list'
Exception on /dodajwpis [POST]
Traceback (most recent call last):
  File "C:\Users\mrend\Desktop\mysite\venv\lib\site-packages\flask\app.py", line 2446, in wsgi_app
    response = self.full_dispatch_request()
  File "C:\Users\mrend\Desktop\mysite\venv\lib\site-packages\flask\app.py", line 1951, in full_dispatch_request
    rv = self.handle_user_exception(e)
  File "C:\Users\mrend\Desktop\mysite\venv\lib\site-packages\flask\app.py", line 1820, in handle_user_exception
    reraise(exc_type, exc_value, tb)
  File "C:\Users\mrend\Desktop\mysite\venv\lib\site-packages\flask\_compat.py", line 39, in reraise
    raise value
  File "C:\Users\mrend\Desktop\mysite\venv\lib\site-packages\flask\app.py", line 1949, in full_dispatch_request
    rv = self.dispatch_request()
  File "C:\Users\mrend\Desktop\mysite\venv\lib\site-packages\flask\app.py", line 1935, in dispatch_request
    return self.view_functions[rule.endpoint](**req.view_args)
  File "C:\Users\mrend\Desktop\mysite\app\routes\add_post.py", line 58, in add_post
    file.save(os.path.join('app/static/images/', post_id + str(imageAttached)))
TypeError: unsupported operand type(s) for +: 'int' and 'str'
Exception on /dodajwpis [POST]
Traceback (most recent call last):
  File "C:\Users\mrend\Desktop\mysite\venv\lib\site-packages\flask\app.py", line 2446, in wsgi_app
    response = self.full_dispatch_request()
  File "C:\Users\mrend\Desktop\mysite\venv\lib\site-packages\flask\app.py", line 1951, in full_dispatch_request
    rv = self.handle_user_exception(e)
  File "C:\Users\mrend\Desktop\mysite\venv\lib\site-packages\flask\app.py", line 1820, in handle_user_exception
    reraise(exc_type, exc_value, tb)
  File "C:\Users\mrend\Desktop\mysite\venv\lib\site-packages\flask\_compat.py", line 39, in reraise
    raise value
  File "C:\Users\mrend\Desktop\mysite\venv\lib\site-packages\flask\app.py", line 1949, in full_dispatch_request
    rv = self.dispatch_request()
  File "C:\Users\mrend\Desktop\mysite\venv\lib\site-packages\flask\app.py", line 1935, in dispatch_request
    return self.view_functions[rule.endpoint](**req.view_args)
  File "C:\Users\mrend\Desktop\mysite\app\routes\add_post.py", line 58, in add_post
    file.save(os.path.join('app/static/images/', str(post_id) + imageAttached.join('')))
AttributeError: 'list' object has no attribute 'join'
Exception on /dodajwpis [POST]
Traceback (most recent call last):
  File "C:\Users\mrend\Desktop\mysite\venv\lib\site-packages\MySQLdb\cursors.py", line 204, in execute
    query = query % args
TypeError: not all arguments converted during bytes formatting

During handling of the above exception, another exception occurred:

Traceback (most recent call last):
  File "C:\Users\mrend\Desktop\mysite\venv\lib\site-packages\flask\app.py", line 2446, in wsgi_app
    response = self.full_dispatch_request()
  File "C:\Users\mrend\Desktop\mysite\venv\lib\site-packages\flask\app.py", line 1951, in full_dispatch_request
    rv = self.handle_user_exception(e)
  File "C:\Users\mrend\Desktop\mysite\venv\lib\site-packages\flask\app.py", line 1820, in handle_user_exception
    reraise(exc_type, exc_value, tb)
  File "C:\Users\mrend\Desktop\mysite\venv\lib\site-packages\flask\_compat.py", line 39, in reraise
    raise value
  File "C:\Users\mrend\Desktop\mysite\venv\lib\site-packages\flask\app.py", line 1949, in full_dispatch_request
    rv = self.dispatch_request()
  File "C:\Users\mrend\Desktop\mysite\venv\lib\site-packages\flask\app.py", line 1935, in dispatch_request
    return self.view_functions[rule.endpoint](**req.view_args)
  File "C:\Users\mrend\Desktop\mysite\app\routes\add_post.py", line 44, in add_post
    cur.execute("INSERT INTO wpisy (tresc, autor, data, img) VALUES (%s,%s,%s)", (content, author, actualtime, imageAttached))
  File "C:\Users\mrend\Desktop\mysite\venv\lib\site-packages\MySQLdb\cursors.py", line 206, in execute
    raise ProgrammingError(str(m))
MySQLdb._exceptions.ProgrammingError: not all arguments converted during bytes formatting
Exception on /dodajwpis [POST]
Traceback (most recent call last):
  File "C:\Users\mrend\Desktop\mysite\venv\lib\site-packages\flask\app.py", line 2446, in wsgi_app
    response = self.full_dispatch_request()
  File "C:\Users\mrend\Desktop\mysite\venv\lib\site-packages\flask\app.py", line 1951, in full_dispatch_request
    rv = self.handle_user_exception(e)
  File "C:\Users\mrend\Desktop\mysite\venv\lib\site-packages\flask\app.py", line 1820, in handle_user_exception
    reraise(exc_type, exc_value, tb)
  File "C:\Users\mrend\Desktop\mysite\venv\lib\site-packages\flask\_compat.py", line 39, in reraise
    raise value
  File "C:\Users\mrend\Desktop\mysite\venv\lib\site-packages\flask\app.py", line 1949, in full_dispatch_request
    rv = self.dispatch_request()
  File "C:\Users\mrend\Desktop\mysite\venv\lib\site-packages\flask\app.py", line 1935, in dispatch_request
    return self.view_functions[rule.endpoint](**req.view_args)
  File "C:\Users\mrend\Desktop\mysite\app\routes\add_post.py", line 58, in add_post
    file_name = post_id + "".join(imageAttached)
TypeError: unsupported operand type(s) for +: 'int' and 'str'
Exception on /dodajwpis [POST]
Traceback (most recent call last):
  File "C:\Users\mrend\Desktop\mysite\venv\lib\site-packages\MySQLdb\cursors.py", line 204, in execute
    query = query % args
TypeError: not all arguments converted during bytes formatting

During handling of the above exception, another exception occurred:

Traceback (most recent call last):
  File "C:\Users\mrend\Desktop\mysite\venv\lib\site-packages\flask\app.py", line 2446, in wsgi_app
    response = self.full_dispatch_request()
  File "C:\Users\mrend\Desktop\mysite\venv\lib\site-packages\flask\app.py", line 1951, in full_dispatch_request
    rv = self.handle_user_exception(e)
  File "C:\Users\mrend\Desktop\mysite\venv\lib\site-packages\flask\app.py", line 1820, in handle_user_exception
    reraise(exc_type, exc_value, tb)
  File "C:\Users\mrend\Desktop\mysite\venv\lib\site-packages\flask\_compat.py", line 39, in reraise
    raise value
  File "C:\Users\mrend\Desktop\mysite\venv\lib\site-packages\flask\app.py", line 1949, in full_dispatch_request
    rv = self.dispatch_request()
  File "C:\Users\mrend\Desktop\mysite\venv\lib\site-packages\flask\app.py", line 1935, in dispatch_request
    return self.view_functions[rule.endpoint](**req.view_args)
  File "C:\Users\mrend\Desktop\mysite\app\routes\add_post.py", line 59, in add_post
    cur.execute("UPDATE wpisy SET img=%s", file_name)
  File "C:\Users\mrend\Desktop\mysite\venv\lib\site-packages\MySQLdb\cursors.py", line 206, in execute
    raise ProgrammingError(str(m))
MySQLdb._exceptions.ProgrammingError: not all arguments converted during bytes formatting
Exception on /dodajwpis [POST]
Traceback (most recent call last):
  File "C:\Users\mrend\Desktop\mysite\venv\lib\site-packages\flask\app.py", line 2446, in wsgi_app
    response = self.full_dispatch_request()
  File "C:\Users\mrend\Desktop\mysite\venv\lib\site-packages\flask\app.py", line 1951, in full_dispatch_request
    rv = self.handle_user_exception(e)
  File "C:\Users\mrend\Desktop\mysite\venv\lib\site-packages\flask\app.py", line 1820, in handle_user_exception
    reraise(exc_type, exc_value, tb)
  File "C:\Users\mrend\Desktop\mysite\venv\lib\site-packages\flask\_compat.py", line 39, in reraise
    raise value
  File "C:\Users\mrend\Desktop\mysite\venv\lib\site-packages\flask\app.py", line 1949, in full_dispatch_request
    rv = self.dispatch_request()
  File "C:\Users\mrend\Desktop\mysite\venv\lib\site-packages\flask\app.py", line 1935, in dispatch_request
    return self.view_functions[rule.endpoint](**req.view_args)
  File "C:\Users\mrend\Desktop\mysite\app\routes\add_post.py", line 59, in add_post
    cur.execute("UPDATE wpisy SET img=%s WHERE id=%s", file_name, post_id)
TypeError: execute() takes from 2 to 3 positional arguments but 4 were given
Exception on /dodajwpis [POST]
Traceback (most recent call last):
  File "C:\Users\mrend\Desktop\mysite\venv\lib\site-packages\flask\app.py", line 2446, in wsgi_app
    response = self.full_dispatch_request()
  File "C:\Users\mrend\Desktop\mysite\venv\lib\site-packages\flask\app.py", line 1951, in full_dispatch_request
    rv = self.handle_user_exception(e)
  File "C:\Users\mrend\Desktop\mysite\venv\lib\site-packages\flask\app.py", line 1820, in handle_user_exception
    reraise(exc_type, exc_value, tb)
  File "C:\Users\mrend\Desktop\mysite\venv\lib\site-packages\flask\_compat.py", line 39, in reraise
    raise value
  File "C:\Users\mrend\Desktop\mysite\venv\lib\site-packages\flask\app.py", line 1949, in full_dispatch_request
    rv = self.dispatch_request()
  File "C:\Users\mrend\Desktop\mysite\venv\lib\site-packages\flask\app.py", line 1935, in dispatch_request
    return self.view_functions[rule.endpoint](**req.view_args)
  File "C:\Users\mrend\Desktop\mysite\app\routes\add_post.py", line 59, in add_post
    cur.execute("INSERT INTO wpisy (img) VALUES(%s) WHERE id=%s", (file_name, post_id))
  File "C:\Users\mrend\Desktop\mysite\venv\lib\site-packages\MySQLdb\cursors.py", line 209, in execute
    res = self._query(query)
  File "C:\Users\mrend\Desktop\mysite\venv\lib\site-packages\MySQLdb\cursors.py", line 315, in _query
    db.query(q)
  File "C:\Users\mrend\Desktop\mysite\venv\lib\site-packages\MySQLdb\connections.py", line 239, in query
    _mysql.connection.query(self, query)
MySQLdb._exceptions.ProgrammingError: (1064, "You have an error in your SQL syntax; check the manual that corresponds to your MariaDB server version for the right syntax to use near 'WHERE id=366' at line 1")
Exception on /dodajwpis [POST]
Traceback (most recent call last):
  File "C:\Users\mrend\Desktop\mysite\venv\lib\site-packages\flask\app.py", line 2446, in wsgi_app
    response = self.full_dispatch_request()
  File "C:\Users\mrend\Desktop\mysite\venv\lib\site-packages\flask\app.py", line 1951, in full_dispatch_request
    rv = self.handle_user_exception(e)
  File "C:\Users\mrend\Desktop\mysite\venv\lib\site-packages\flask\app.py", line 1820, in handle_user_exception
    reraise(exc_type, exc_value, tb)
  File "C:\Users\mrend\Desktop\mysite\venv\lib\site-packages\flask\_compat.py", line 39, in reraise
    raise value
  File "C:\Users\mrend\Desktop\mysite\venv\lib\site-packages\flask\app.py", line 1949, in full_dispatch_request
    rv = self.dispatch_request()
  File "C:\Users\mrend\Desktop\mysite\venv\lib\site-packages\flask\app.py", line 1935, in dispatch_request
    return self.view_functions[rule.endpoint](**req.view_args)
  File "C:\Users\mrend\Desktop\mysite\app\routes\add_post.py", line 59, in add_post
    cur.execute("INSERT INTO wpisy (img) VALUES (%s) WHERE id=%s", (file_name, post_id))
  File "C:\Users\mrend\Desktop\mysite\venv\lib\site-packages\MySQLdb\cursors.py", line 209, in execute
    res = self._query(query)
  File "C:\Users\mrend\Desktop\mysite\venv\lib\site-packages\MySQLdb\cursors.py", line 315, in _query
    db.query(q)
  File "C:\Users\mrend\Desktop\mysite\venv\lib\site-packages\MySQLdb\connections.py", line 239, in query
    _mysql.connection.query(self, query)
MySQLdb._exceptions.ProgrammingError: (1064, "You have an error in your SQL syntax; check the manual that corresponds to your MariaDB server version for the right syntax to use near 'WHERE id=367' at line 1")
Exception on /dodajwpis [POST]
Traceback (most recent call last):
  File "C:\Users\mrend\Desktop\mysite\venv\lib\site-packages\flask\app.py", line 2446, in wsgi_app
    response = self.full_dispatch_request()
  File "C:\Users\mrend\Desktop\mysite\venv\lib\site-packages\flask\app.py", line 1951, in full_dispatch_request
    rv = self.handle_user_exception(e)
  File "C:\Users\mrend\Desktop\mysite\venv\lib\site-packages\flask\app.py", line 1820, in handle_user_exception
    reraise(exc_type, exc_value, tb)
  File "C:\Users\mrend\Desktop\mysite\venv\lib\site-packages\flask\_compat.py", line 39, in reraise
    raise value
  File "C:\Users\mrend\Desktop\mysite\venv\lib\site-packages\flask\app.py", line 1949, in full_dispatch_request
    rv = self.dispatch_request()
  File "C:\Users\mrend\Desktop\mysite\venv\lib\site-packages\flask\app.py", line 1935, in dispatch_request
    return self.view_functions[rule.endpoint](**req.view_args)
  File "C:\Users\mrend\Desktop\mysite\app\routes\add_post.py", line 59, in add_post
    cur.execute("INSERT INTO wpisy (img) VALUES (%s) WHERE id=%s", (file_name, post_id))
  File "C:\Users\mrend\Desktop\mysite\venv\lib\site-packages\MySQLdb\cursors.py", line 209, in execute
    res = self._query(query)
  File "C:\Users\mrend\Desktop\mysite\venv\lib\site-packages\MySQLdb\cursors.py", line 315, in _query
    db.query(q)
  File "C:\Users\mrend\Desktop\mysite\venv\lib\site-packages\MySQLdb\connections.py", line 239, in query
    _mysql.connection.query(self, query)
MySQLdb._exceptions.ProgrammingError: (1064, "You have an error in your SQL syntax; check the manual that corresponds to your MariaDB server version for the right syntax to use near 'WHERE id=368' at line 1")
Exception on / [GET]
Traceback (most recent call last):
  File "C:\Users\mrend\Desktop\mysite\venv\lib\site-packages\flask\app.py", line 2446, in wsgi_app
    response = self.full_dispatch_request()
  File "C:\Users\mrend\Desktop\mysite\venv\lib\site-packages\flask\app.py", line 1951, in full_dispatch_request
    rv = self.handle_user_exception(e)
  File "C:\Users\mrend\Desktop\mysite\venv\lib\site-packages\flask\app.py", line 1820, in handle_user_exception
    reraise(exc_type, exc_value, tb)
  File "C:\Users\mrend\Desktop\mysite\venv\lib\site-packages\flask\_compat.py", line 39, in reraise
    raise value
  File "C:\Users\mrend\Desktop\mysite\venv\lib\site-packages\flask\app.py", line 1949, in full_dispatch_request
    rv = self.dispatch_request()
  File "C:\Users\mrend\Desktop\mysite\venv\lib\site-packages\flask\app.py", line 1935, in dispatch_request
    return self.view_functions[rule.endpoint](**req.view_args)
  File "C:\Users\mrend\Desktop\mysite\app\routes\index.py", line 13, in index
    cur = mysql.connection.cursor()
  File "C:\Users\mrend\Desktop\mysite\venv\lib\site-packages\flask_mysqldb\__init__.py", line 94, in connection
    ctx.mysql_db = self.connect
  File "C:\Users\mrend\Desktop\mysite\venv\lib\site-packages\flask_mysqldb\__init__.py", line 81, in connect
    return MySQLdb.connect(**kwargs)
  File "C:\Users\mrend\Desktop\mysite\venv\lib\site-packages\MySQLdb\__init__.py", line 84, in Connect
    return Connection(*args, **kwargs)
  File "C:\Users\mrend\Desktop\mysite\venv\lib\site-packages\MySQLdb\connections.py", line 179, in __init__
    super(Connection, self).__init__(*args, **kwargs2)
MySQLdb._exceptions.OperationalError: (2003, "Can't connect to MySQL server on 'localhost' (10061)")
Exception on / [GET]
Traceback (most recent call last):
  File "C:\Users\mrend\Desktop\mysite\venv\lib\site-packages\flask\app.py", line 2446, in wsgi_app
    response = self.full_dispatch_request()
  File "C:\Users\mrend\Desktop\mysite\venv\lib\site-packages\flask\app.py", line 1951, in full_dispatch_request
    rv = self.handle_user_exception(e)
  File "C:\Users\mrend\Desktop\mysite\venv\lib\site-packages\flask\app.py", line 1820, in handle_user_exception
    reraise(exc_type, exc_value, tb)
  File "C:\Users\mrend\Desktop\mysite\venv\lib\site-packages\flask\_compat.py", line 39, in reraise
    raise value
  File "C:\Users\mrend\Desktop\mysite\venv\lib\site-packages\flask\app.py", line 1949, in full_dispatch_request
    rv = self.dispatch_request()
  File "C:\Users\mrend\Desktop\mysite\venv\lib\site-packages\flask\app.py", line 1935, in dispatch_request
    return self.view_functions[rule.endpoint](**req.view_args)
  File "C:\Users\mrend\Desktop\mysite\app\routes\index.py", line 13, in index
    cur = mysql.connection.cursor()
  File "C:\Users\mrend\Desktop\mysite\venv\lib\site-packages\flask_mysqldb\__init__.py", line 94, in connection
    ctx.mysql_db = self.connect
  File "C:\Users\mrend\Desktop\mysite\venv\lib\site-packages\flask_mysqldb\__init__.py", line 81, in connect
    return MySQLdb.connect(**kwargs)
  File "C:\Users\mrend\Desktop\mysite\venv\lib\site-packages\MySQLdb\__init__.py", line 84, in Connect
    return Connection(*args, **kwargs)
  File "C:\Users\mrend\Desktop\mysite\venv\lib\site-packages\MySQLdb\connections.py", line 179, in __init__
    super(Connection, self).__init__(*args, **kwargs2)
MySQLdb._exceptions.OperationalError: (2003, "Can't connect to MySQL server on 'localhost' (10061)")
Exception on /dodaj_komentarz [POST]
Traceback (most recent call last):
  File "C:\Users\mrend\Desktop\mysite\venv\lib\site-packages\flask\app.py", line 2116, in make_response
    rv = self.response_class.force_type(rv, request.environ)
  File "C:\Users\mrend\Desktop\mysite\venv\lib\site-packages\werkzeug\wrappers\base_response.py", line 269, in force_type
    response = BaseResponse(*_run_wsgi_app(response, environ))
  File "C:\Users\mrend\Desktop\mysite\venv\lib\site-packages\werkzeug\wrappers\base_response.py", line 26, in _run_wsgi_app
    return _run_wsgi_app(*args)
  File "C:\Users\mrend\Desktop\mysite\venv\lib\site-packages\werkzeug\test.py", line 1096, in run_wsgi_app
    app_rv = app(environ, start_response)
  File "C:\Users\mrend\Desktop\mysite\venv\lib\site-packages\werkzeug\exceptions.py", line 822, in abort
    return _aborter(status, *args, **kwargs)
  File "C:\Users\mrend\Desktop\mysite\venv\lib\site-packages\werkzeug\exceptions.py", line 805, in __call__
    if code not in self.mapping:
TypeError: unhashable type: 'dict'

During handling of the above exception, another exception occurred:

Traceback (most recent call last):
  File "C:\Users\mrend\Desktop\mysite\venv\lib\site-packages\flask\app.py", line 2446, in wsgi_app
    response = self.full_dispatch_request()
  File "C:\Users\mrend\Desktop\mysite\venv\lib\site-packages\flask\app.py", line 1952, in full_dispatch_request
    return self.finalize_request(rv)
  File "C:\Users\mrend\Desktop\mysite\venv\lib\site-packages\flask\app.py", line 1967, in finalize_request
    response = self.make_response(rv)
  File "C:\Users\mrend\Desktop\mysite\venv\lib\site-packages\flask\app.py", line 2124, in make_response
    reraise(TypeError, new_error, sys.exc_info()[2])
  File "C:\Users\mrend\Desktop\mysite\venv\lib\site-packages\flask\_compat.py", line 38, in reraise
    raise value.with_traceback(tb)
  File "C:\Users\mrend\Desktop\mysite\venv\lib\site-packages\flask\app.py", line 2116, in make_response
    rv = self.response_class.force_type(rv, request.environ)
  File "C:\Users\mrend\Desktop\mysite\venv\lib\site-packages\werkzeug\wrappers\base_response.py", line 269, in force_type
    response = BaseResponse(*_run_wsgi_app(response, environ))
  File "C:\Users\mrend\Desktop\mysite\venv\lib\site-packages\werkzeug\wrappers\base_response.py", line 26, in _run_wsgi_app
    return _run_wsgi_app(*args)
  File "C:\Users\mrend\Desktop\mysite\venv\lib\site-packages\werkzeug\test.py", line 1096, in run_wsgi_app
    app_rv = app(environ, start_response)
  File "C:\Users\mrend\Desktop\mysite\venv\lib\site-packages\werkzeug\exceptions.py", line 822, in abort
    return _aborter(status, *args, **kwargs)
  File "C:\Users\mrend\Desktop\mysite\venv\lib\site-packages\werkzeug\exceptions.py", line 805, in __call__
    if code not in self.mapping:
TypeError: unhashable type: 'dict'
The view function did not return a valid response. The return type must be a string, dict, tuple, Response instance, or WSGI callable, but it was a function.
Exception on /dodaj_komentarz [POST]
Traceback (most recent call last):
  File "C:\Users\mrend\Desktop\mysite\venv\lib\site-packages\flask\app.py", line 1949, in full_dispatch_request
    rv = self.dispatch_request()
  File "C:\Users\mrend\Desktop\mysite\venv\lib\site-packages\flask\app.py", line 1935, in dispatch_request
    return self.view_functions[rule.endpoint](**req.view_args)
  File "C:\Users\mrend\Desktop\mysite\venv\lib\site-packages\flask_limiter\extension.py", line 696, in __inner
    self.__check_request_limit(False)
  File "C:\Users\mrend\Desktop\mysite\venv\lib\site-packages\flask_limiter\extension.py", line 612, in __check_request_limit
    six.reraise(*sys.exc_info())
  File "C:\Users\mrend\Desktop\mysite\venv\lib\site-packages\six.py", line 703, in reraise
    raise value
  File "C:\Users\mrend\Desktop\mysite\venv\lib\site-packages\flask_limiter\extension.py", line 609, in __check_request_limit
    self.__evaluate_limits(endpoint, all_limits)
  File "C:\Users\mrend\Desktop\mysite\venv\lib\site-packages\flask_limiter\extension.py", line 491, in __evaluate_limits
    raise RateLimitExceeded(failed_limit)
flask_limiter.errors.RateLimitExceeded: 429 Too Many Requests: 1 per 1 second

During handling of the above exception, another exception occurred:

Traceback (most recent call last):
  File "C:\Users\mrend\Desktop\mysite\venv\lib\site-packages\flask\app.py", line 2446, in wsgi_app
    response = self.full_dispatch_request()
  File "C:\Users\mrend\Desktop\mysite\venv\lib\site-packages\flask\app.py", line 1951, in full_dispatch_request
    rv = self.handle_user_exception(e)
  File "C:\Users\mrend\Desktop\mysite\venv\lib\site-packages\flask\app.py", line 1815, in handle_user_exception
    return self.handle_http_exception(e)
  File "C:\Users\mrend\Desktop\mysite\venv\lib\site-packages\flask\app.py", line 1743, in handle_http_exception
    return handler(e)
  File "C:\Users\mrend\Desktop\mysite\app\utils\errors.py", line 19, in ratelimit_handler
    if request.is_xhr or request.accept_mimetypes.accept_json:
  File "C:\Users\mrend\Desktop\mysite\venv\lib\site-packages\werkzeug\local.py", line 347, in __getattr__
    return getattr(self._get_current_object(), name)
AttributeError: 'Request' object has no attribute 'is_xhr'
Exception on /dodaj_komentarz [POST]
Traceback (most recent call last):
  File "C:\Users\mrend\Desktop\mysite\venv\lib\site-packages\flask\app.py", line 1949, in full_dispatch_request
    rv = self.dispatch_request()
  File "C:\Users\mrend\Desktop\mysite\venv\lib\site-packages\flask\app.py", line 1935, in dispatch_request
    return self.view_functions[rule.endpoint](**req.view_args)
  File "C:\Users\mrend\Desktop\mysite\venv\lib\site-packages\flask_limiter\extension.py", line 696, in __inner
    self.__check_request_limit(False)
  File "C:\Users\mrend\Desktop\mysite\venv\lib\site-packages\flask_limiter\extension.py", line 612, in __check_request_limit
    six.reraise(*sys.exc_info())
  File "C:\Users\mrend\Desktop\mysite\venv\lib\site-packages\six.py", line 703, in reraise
    raise value
  File "C:\Users\mrend\Desktop\mysite\venv\lib\site-packages\flask_limiter\extension.py", line 609, in __check_request_limit
    self.__evaluate_limits(endpoint, all_limits)
  File "C:\Users\mrend\Desktop\mysite\venv\lib\site-packages\flask_limiter\extension.py", line 491, in __evaluate_limits
    raise RateLimitExceeded(failed_limit)
flask_limiter.errors.RateLimitExceeded: 429 Too Many Requests: 1 per 1 second

During handling of the above exception, another exception occurred:

Traceback (most recent call last):
  File "C:\Users\mrend\Desktop\mysite\venv\lib\site-packages\flask\app.py", line 2446, in wsgi_app
    response = self.full_dispatch_request()
  File "C:\Users\mrend\Desktop\mysite\venv\lib\site-packages\flask\app.py", line 1951, in full_dispatch_request
    rv = self.handle_user_exception(e)
  File "C:\Users\mrend\Desktop\mysite\venv\lib\site-packages\flask\app.py", line 1815, in handle_user_exception
    return self.handle_http_exception(e)
  File "C:\Users\mrend\Desktop\mysite\venv\lib\site-packages\flask\app.py", line 1743, in handle_http_exception
    return handler(e)
  File "C:\Users\mrend\Desktop\mysite\app\utils\errors.py", line 19, in ratelimit_handler
    if request.is_xhr or request.accept_mimetypes.accept_json:
  File "C:\Users\mrend\Desktop\mysite\venv\lib\site-packages\werkzeug\local.py", line 347, in __getattr__
    return getattr(self._get_current_object(), name)
AttributeError: 'Request' object has no attribute 'is_xhr'
Exception on /dodaj_komentarz [POST]
Traceback (most recent call last):
  File "C:\Users\mrend\Desktop\mysite\venv\lib\site-packages\flask\app.py", line 1949, in full_dispatch_request
    rv = self.dispatch_request()
  File "C:\Users\mrend\Desktop\mysite\venv\lib\site-packages\flask\app.py", line 1935, in dispatch_request
    return self.view_functions[rule.endpoint](**req.view_args)
  File "C:\Users\mrend\Desktop\mysite\venv\lib\site-packages\flask_limiter\extension.py", line 696, in __inner
    self.__check_request_limit(False)
  File "C:\Users\mrend\Desktop\mysite\venv\lib\site-packages\flask_limiter\extension.py", line 612, in __check_request_limit
    six.reraise(*sys.exc_info())
  File "C:\Users\mrend\Desktop\mysite\venv\lib\site-packages\six.py", line 703, in reraise
    raise value
  File "C:\Users\mrend\Desktop\mysite\venv\lib\site-packages\flask_limiter\extension.py", line 609, in __check_request_limit
    self.__evaluate_limits(endpoint, all_limits)
  File "C:\Users\mrend\Desktop\mysite\venv\lib\site-packages\flask_limiter\extension.py", line 491, in __evaluate_limits
    raise RateLimitExceeded(failed_limit)
flask_limiter.errors.RateLimitExceeded: 429 Too Many Requests: 5 per 1 minute

During handling of the above exception, another exception occurred:

Traceback (most recent call last):
  File "C:\Users\mrend\Desktop\mysite\venv\lib\site-packages\flask\app.py", line 2446, in wsgi_app
    response = self.full_dispatch_request()
  File "C:\Users\mrend\Desktop\mysite\venv\lib\site-packages\flask\app.py", line 1951, in full_dispatch_request
    rv = self.handle_user_exception(e)
  File "C:\Users\mrend\Desktop\mysite\venv\lib\site-packages\flask\app.py", line 1815, in handle_user_exception
    return self.handle_http_exception(e)
  File "C:\Users\mrend\Desktop\mysite\venv\lib\site-packages\flask\app.py", line 1743, in handle_http_exception
    return handler(e)
  File "C:\Users\mrend\Desktop\mysite\app\utils\errors.py", line 19, in ratelimit_handler
    if request.is_xhr or request.accept_mimetypes.accept_json:
  File "C:\Users\mrend\Desktop\mysite\venv\lib\site-packages\werkzeug\local.py", line 347, in __getattr__
    return getattr(self._get_current_object(), name)
AttributeError: 'Request' object has no attribute 'is_xhr'
Exception on /login [POST]
Traceback (most recent call last):
  File "C:\Users\mrend\Desktop\mysite\venv\lib\site-packages\flask\app.py", line 2446, in wsgi_app
    response = self.full_dispatch_request()
  File "C:\Users\mrend\Desktop\mysite\venv\lib\site-packages\flask\app.py", line 1951, in full_dispatch_request
    rv = self.handle_user_exception(e)
  File "C:\Users\mrend\Desktop\mysite\venv\lib\site-packages\flask\app.py", line 1820, in handle_user_exception
    reraise(exc_type, exc_value, tb)
  File "C:\Users\mrend\Desktop\mysite\venv\lib\site-packages\flask\_compat.py", line 39, in reraise
    raise value
  File "C:\Users\mrend\Desktop\mysite\venv\lib\site-packages\flask\app.py", line 1949, in full_dispatch_request
    rv = self.dispatch_request()
  File "C:\Users\mrend\Desktop\mysite\venv\lib\site-packages\flask\app.py", line 1935, in dispatch_request
    return self.view_functions[rule.endpoint](**req.view_args)
  File "C:\Users\mrend\Desktop\mysite\app\routes\login.py", line 21, in login
    cur.execute("UPDATE users SET ip=%s WHERE id=%s", (request.remote_addr, user['id']))
  File "C:\Users\mrend\Desktop\mysite\venv\lib\site-packages\MySQLdb\cursors.py", line 186, in execute
    while self.nextset():
  File "C:\Users\mrend\Desktop\mysite\venv\lib\site-packages\MySQLdb\cursors.py", line 138, in nextset
    db = self._get_db()
  File "C:\Users\mrend\Desktop\mysite\venv\lib\site-packages\MySQLdb\cursors.py", line 171, in _get_db
    raise ProgrammingError("cursor closed")
MySQLdb._exceptions.ProgrammingError: cursor closed
Exception on / [GET]
Traceback (most recent call last):
  File "C:\Users\mrend\Desktop\mysite\venv\lib\site-packages\flask\app.py", line 2446, in wsgi_app
    response = self.full_dispatch_request()
  File "C:\Users\mrend\Desktop\mysite\venv\lib\site-packages\flask\app.py", line 1951, in full_dispatch_request
    rv = self.handle_user_exception(e)
  File "C:\Users\mrend\Desktop\mysite\venv\lib\site-packages\flask\app.py", line 1820, in handle_user_exception
    reraise(exc_type, exc_value, tb)
  File "C:\Users\mrend\Desktop\mysite\venv\lib\site-packages\flask\_compat.py", line 39, in reraise
    raise value
  File "C:\Users\mrend\Desktop\mysite\venv\lib\site-packages\flask\app.py", line 1949, in full_dispatch_request
    rv = self.dispatch_request()
  File "C:\Users\mrend\Desktop\mysite\venv\lib\site-packages\flask\app.py", line 1935, in dispatch_request
    return self.view_functions[rule.endpoint](**req.view_args)
  File "C:\Users\mrend\Desktop\mysite\app\routes\index.py", line 22, in index
    return render_template('index.html', posts=posts, comments=comments, likes=likes, form=form, users=users)
  File "C:\Users\mrend\Desktop\mysite\venv\lib\site-packages\flask\templating.py", line 137, in render_template
    return _render(
  File "C:\Users\mrend\Desktop\mysite\venv\lib\site-packages\flask\templating.py", line 120, in _render
    rv = template.render(context)
  File "C:\Users\mrend\Desktop\mysite\venv\lib\site-packages\jinja2\environment.py", line 1090, in render
    self.environment.handle_exception()
  File "C:\Users\mrend\Desktop\mysite\venv\lib\site-packages\jinja2\environment.py", line 832, in handle_exception
    reraise(*rewrite_traceback_stack(source=source))
  File "C:\Users\mrend\Desktop\mysite\venv\lib\site-packages\jinja2\_compat.py", line 28, in reraise
    raise value.with_traceback(tb)
  File "C:\Users\mrend\Desktop\mysite\app\templates\index.html", line 1, in top-level template code
    {% extends 'base.html' %}
  File "C:\Users\mrend\Desktop\mysite\app\templates\base.html", line 30, in top-level template code
    {% block body %}
  File "C:\Users\mrend\Desktop\mysite\app\templates\index.html", line 5, in block "body"
    {% include 'navbar.html' %}
  File "C:\Users\mrend\Desktop\mysite\app\templates\navbar.html", line 31, in top-level template code
    <a class="dropdown-item" href="{{ url_for('settings_blueprint.ustawieniaget') }}">Ustawienia</a>
  File "C:\Users\mrend\Desktop\mysite\venv\lib\site-packages\flask\helpers.py", line 370, in url_for
    return appctx.app.handle_url_build_error(error, endpoint, values)
  File "C:\Users\mrend\Desktop\mysite\venv\lib\site-packages\flask\app.py", line 2215, in handle_url_build_error
    reraise(exc_type, exc_value, tb)
  File "C:\Users\mrend\Desktop\mysite\venv\lib\site-packages\flask\_compat.py", line 39, in reraise
    raise value
  File "C:\Users\mrend\Desktop\mysite\venv\lib\site-packages\flask\helpers.py", line 357, in url_for
    rv = url_adapter.build(
  File "C:\Users\mrend\Desktop\mysite\venv\lib\site-packages\werkzeug\routing.py", line 2179, in build
    raise BuildError(endpoint, values, method, self)
werkzeug.routing.BuildError: Could not build url for endpoint 'settings_blueprint.ustawieniaget'. Did you mean 'settings_blueprint.zmienopis' instead?
Exception on / [GET]
Traceback (most recent call last):
  File "C:\Users\mrend\Desktop\mysite\venv\lib\site-packages\flask\app.py", line 2446, in wsgi_app
    response = self.full_dispatch_request()
  File "C:\Users\mrend\Desktop\mysite\venv\lib\site-packages\flask\app.py", line 1951, in full_dispatch_request
    rv = self.handle_user_exception(e)
  File "C:\Users\mrend\Desktop\mysite\venv\lib\site-packages\flask\app.py", line 1820, in handle_user_exception
    reraise(exc_type, exc_value, tb)
  File "C:\Users\mrend\Desktop\mysite\venv\lib\site-packages\flask\_compat.py", line 39, in reraise
    raise value
  File "C:\Users\mrend\Desktop\mysite\venv\lib\site-packages\flask\app.py", line 1949, in full_dispatch_request
    rv = self.dispatch_request()
  File "C:\Users\mrend\Desktop\mysite\venv\lib\site-packages\flask\app.py", line 1935, in dispatch_request
    return self.view_functions[rule.endpoint](**req.view_args)
  File "C:\Users\mrend\Desktop\mysite\app\routes\index.py", line 22, in index
    return render_template('index.html', posts=posts, comments=comments, likes=likes, form=form, users=users)
  File "C:\Users\mrend\Desktop\mysite\venv\lib\site-packages\flask\templating.py", line 137, in render_template
    return _render(
  File "C:\Users\mrend\Desktop\mysite\venv\lib\site-packages\flask\templating.py", line 120, in _render
    rv = template.render(context)
  File "C:\Users\mrend\Desktop\mysite\venv\lib\site-packages\jinja2\environment.py", line 1090, in render
    self.environment.handle_exception()
  File "C:\Users\mrend\Desktop\mysite\venv\lib\site-packages\jinja2\environment.py", line 832, in handle_exception
    reraise(*rewrite_traceback_stack(source=source))
  File "C:\Users\mrend\Desktop\mysite\venv\lib\site-packages\jinja2\_compat.py", line 28, in reraise
    raise value.with_traceback(tb)
  File "C:\Users\mrend\Desktop\mysite\app\templates\index.html", line 1, in top-level template code
    {% extends 'base.html' %}
  File "C:\Users\mrend\Desktop\mysite\app\templates\base.html", line 30, in top-level template code
    {% block body %}
  File "C:\Users\mrend\Desktop\mysite\app\templates\index.html", line 5, in block "body"
    {% include 'navbar.html' %}
  File "C:\Users\mrend\Desktop\mysite\app\templates\navbar.html", line 31, in top-level template code
    <a class="dropdown-item" href="{{ url_for('settings_blueprint.ustawieniaget') }}">Ustawienia</a>
  File "C:\Users\mrend\Desktop\mysite\venv\lib\site-packages\flask\helpers.py", line 370, in url_for
    return appctx.app.handle_url_build_error(error, endpoint, values)
  File "C:\Users\mrend\Desktop\mysite\venv\lib\site-packages\flask\app.py", line 2215, in handle_url_build_error
    reraise(exc_type, exc_value, tb)
  File "C:\Users\mrend\Desktop\mysite\venv\lib\site-packages\flask\_compat.py", line 39, in reraise
    raise value
  File "C:\Users\mrend\Desktop\mysite\venv\lib\site-packages\flask\helpers.py", line 357, in url_for
    rv = url_adapter.build(
  File "C:\Users\mrend\Desktop\mysite\venv\lib\site-packages\werkzeug\routing.py", line 2179, in build
    raise BuildError(endpoint, values, method, self)
werkzeug.routing.BuildError: Could not build url for endpoint 'settings_blueprint.ustawieniaget'. Did you mean 'settings_blueprint.zmienopis' instead?
Exception on /ustawienia [GET]
Traceback (most recent call last):
  File "C:\Users\mrend\Desktop\mysite\venv\lib\site-packages\flask\app.py", line 2446, in wsgi_app
    response = self.full_dispatch_request()
  File "C:\Users\mrend\Desktop\mysite\venv\lib\site-packages\flask\app.py", line 1951, in full_dispatch_request
    rv = self.handle_user_exception(e)
  File "C:\Users\mrend\Desktop\mysite\venv\lib\site-packages\flask\app.py", line 1820, in handle_user_exception
    reraise(exc_type, exc_value, tb)
  File "C:\Users\mrend\Desktop\mysite\venv\lib\site-packages\flask\_compat.py", line 39, in reraise
    raise value
  File "C:\Users\mrend\Desktop\mysite\venv\lib\site-packages\flask\app.py", line 1949, in full_dispatch_request
    rv = self.dispatch_request()
  File "C:\Users\mrend\Desktop\mysite\venv\lib\site-packages\flask\app.py", line 1935, in dispatch_request
    return self.view_functions[rule.endpoint](**req.view_args)
  File "C:\Users\mrend\Desktop\mysite\app\routes\settings.py", line 19, in show_settings
    return render_template('ustawienia.html', formr=formr, formp=formp, formo=formo)
  File "C:\Users\mrend\Desktop\mysite\venv\lib\site-packages\flask\templating.py", line 137, in render_template
    return _render(
  File "C:\Users\mrend\Desktop\mysite\venv\lib\site-packages\flask\templating.py", line 120, in _render
    rv = template.render(context)
  File "C:\Users\mrend\Desktop\mysite\venv\lib\site-packages\jinja2\environment.py", line 1090, in render
    self.environment.handle_exception()
  File "C:\Users\mrend\Desktop\mysite\venv\lib\site-packages\jinja2\environment.py", line 832, in handle_exception
    reraise(*rewrite_traceback_stack(source=source))
  File "C:\Users\mrend\Desktop\mysite\venv\lib\site-packages\jinja2\_compat.py", line 28, in reraise
    raise value.with_traceback(tb)
  File "C:\Users\mrend\Desktop\mysite\app\templates\ustawienia.html", line 1, in top-level template code
    {% extends 'base.html' %}
  File "C:\Users\mrend\Desktop\mysite\app\templates\base.html", line 30, in top-level template code
    {% block body %}
  File "C:\Users\mrend\Desktop\mysite\app\templates\ustawienia.html", line 7, in block "body"
    <form action="{{ url_for('settings_blueprint.zmienemail') }}" method="post">
  File "C:\Users\mrend\Desktop\mysite\venv\lib\site-packages\flask\helpers.py", line 370, in url_for
    return appctx.app.handle_url_build_error(error, endpoint, values)
  File "C:\Users\mrend\Desktop\mysite\venv\lib\site-packages\flask\app.py", line 2215, in handle_url_build_error
    reraise(exc_type, exc_value, tb)
  File "C:\Users\mrend\Desktop\mysite\venv\lib\site-packages\flask\_compat.py", line 39, in reraise
    raise value
  File "C:\Users\mrend\Desktop\mysite\venv\lib\site-packages\flask\helpers.py", line 357, in url_for
    rv = url_adapter.build(
  File "C:\Users\mrend\Desktop\mysite\venv\lib\site-packages\werkzeug\routing.py", line 2179, in build
    raise BuildError(endpoint, values, method, self)
werkzeug.routing.BuildError: Could not build url for endpoint 'settings_blueprint.zmienemail'. Did you mean 'settings_blueprint.zmienopis' instead?
Exception on /register [POST]
Traceback (most recent call last):
  File "C:\Users\mrend\Desktop\mysite\venv\lib\site-packages\MySQLdb\cursors.py", line 204, in execute
    query = query % args
TypeError: not enough arguments for format string

During handling of the above exception, another exception occurred:

Traceback (most recent call last):
  File "C:\Users\mrend\Desktop\mysite\venv\lib\site-packages\flask\app.py", line 2446, in wsgi_app
    response = self.full_dispatch_request()
  File "C:\Users\mrend\Desktop\mysite\venv\lib\site-packages\flask\app.py", line 1951, in full_dispatch_request
    rv = self.handle_user_exception(e)
  File "C:\Users\mrend\Desktop\mysite\venv\lib\site-packages\flask\app.py", line 1820, in handle_user_exception
    reraise(exc_type, exc_value, tb)
  File "C:\Users\mrend\Desktop\mysite\venv\lib\site-packages\flask\_compat.py", line 39, in reraise
    raise value
  File "C:\Users\mrend\Desktop\mysite\venv\lib\site-packages\flask\app.py", line 1949, in full_dispatch_request
    rv = self.dispatch_request()
  File "C:\Users\mrend\Desktop\mysite\venv\lib\site-packages\flask\app.py", line 1935, in dispatch_request
    return self.view_functions[rule.endpoint](**req.view_args)
  File "C:\Users\mrend\Desktop\mysite\app\routes\auth.py", line 17, in register
    cur.execute("SELECT login FROM users WHERE login=%s OR email=%s",(login,))
  File "C:\Users\mrend\Desktop\mysite\venv\lib\site-packages\MySQLdb\cursors.py", line 206, in execute
    raise ProgrammingError(str(m))
MySQLdb._exceptions.ProgrammingError: not enough arguments for format string
Exception on / [GET]
Traceback (most recent call last):
  File "C:\Users\mrend\Desktop\mysite\venv\lib\site-packages\flask\app.py", line 2446, in wsgi_app
    response = self.full_dispatch_request()
  File "C:\Users\mrend\Desktop\mysite\venv\lib\site-packages\flask\app.py", line 1951, in full_dispatch_request
    rv = self.handle_user_exception(e)
  File "C:\Users\mrend\Desktop\mysite\venv\lib\site-packages\flask\app.py", line 1820, in handle_user_exception
    reraise(exc_type, exc_value, tb)
  File "C:\Users\mrend\Desktop\mysite\venv\lib\site-packages\flask\_compat.py", line 39, in reraise
    raise value
  File "C:\Users\mrend\Desktop\mysite\venv\lib\site-packages\flask\app.py", line 1949, in full_dispatch_request
    rv = self.dispatch_request()
  File "C:\Users\mrend\Desktop\mysite\venv\lib\site-packages\flask\app.py", line 1935, in dispatch_request
    return self.view_functions[rule.endpoint](**req.view_args)
  File "C:\Users\mrend\Desktop\mysite\app\routes\index.py", line 12, in index
    form = AddPostForm()
  File "C:\Users\mrend\Desktop\mysite\venv\lib\site-packages\wtforms\form.py", line 212, in __call__
    return type.__call__(cls, *args, **kwargs)
  File "C:\Users\mrend\Desktop\mysite\venv\lib\site-packages\flask_wtf\form.py", line 87, in __init__
    super(FlaskForm, self).__init__(formdata=formdata, **kwargs)
  File "C:\Users\mrend\Desktop\mysite\venv\lib\site-packages\wtforms\form.py", line 278, in __init__
    self.process(formdata, obj, data=data, **kwargs)
  File "C:\Users\mrend\Desktop\mysite\venv\lib\site-packages\wtforms\form.py", line 132, in process
    field.process(formdata)
  File "C:\Users\mrend\Desktop\mysite\venv\lib\site-packages\wtforms\csrf\core.py", line 43, in process
    self.current_token = self.csrf_impl.generate_csrf_token(self)
  File "C:\Users\mrend\Desktop\mysite\venv\lib\site-packages\flask_wtf\csrf.py", line 139, in generate_csrf_token
    return generate_csrf(
  File "C:\Users\mrend\Desktop\mysite\venv\lib\site-packages\flask_wtf\csrf.py", line 46, in generate_csrf
    session[field_name] = hashlib.sha1(os.urandom(64)).hexdigest()
  File "C:\Users\mrend\Desktop\mysite\venv\lib\site-packages\werkzeug\local.py", line 350, in __setitem__
    self._get_current_object()[key] = value
  File "C:\Users\mrend\Desktop\mysite\venv\lib\site-packages\flask\sessions.py", line 102, in _fail
    raise RuntimeError(
RuntimeError: The session is unavailable because no secret key was set.  Set the secret_key on the application to something unique and secret.
Exception on / [GET]
Traceback (most recent call last):
  File "C:\Users\mrend\Desktop\mysite\venv\lib\site-packages\flask\app.py", line 2446, in wsgi_app
    response = self.full_dispatch_request()
  File "C:\Users\mrend\Desktop\mysite\venv\lib\site-packages\flask\app.py", line 1951, in full_dispatch_request
    rv = self.handle_user_exception(e)
  File "C:\Users\mrend\Desktop\mysite\venv\lib\site-packages\flask\app.py", line 1820, in handle_user_exception
    reraise(exc_type, exc_value, tb)
  File "C:\Users\mrend\Desktop\mysite\venv\lib\site-packages\flask\_compat.py", line 39, in reraise
    raise value
  File "C:\Users\mrend\Desktop\mysite\venv\lib\site-packages\flask\app.py", line 1949, in full_dispatch_request
    rv = self.dispatch_request()
  File "C:\Users\mrend\Desktop\mysite\venv\lib\site-packages\flask\app.py", line 1935, in dispatch_request
    return self.view_functions[rule.endpoint](**req.view_args)
  File "C:\Users\mrend\Desktop\mysite\app\routes\index.py", line 12, in index
    form = AddPostForm()
  File "C:\Users\mrend\Desktop\mysite\venv\lib\site-packages\wtforms\form.py", line 212, in __call__
    return type.__call__(cls, *args, **kwargs)
  File "C:\Users\mrend\Desktop\mysite\venv\lib\site-packages\flask_wtf\form.py", line 87, in __init__
    super(FlaskForm, self).__init__(formdata=formdata, **kwargs)
  File "C:\Users\mrend\Desktop\mysite\venv\lib\site-packages\wtforms\form.py", line 278, in __init__
    self.process(formdata, obj, data=data, **kwargs)
  File "C:\Users\mrend\Desktop\mysite\venv\lib\site-packages\wtforms\form.py", line 132, in process
    field.process(formdata)
  File "C:\Users\mrend\Desktop\mysite\venv\lib\site-packages\wtforms\csrf\core.py", line 43, in process
    self.current_token = self.csrf_impl.generate_csrf_token(self)
  File "C:\Users\mrend\Desktop\mysite\venv\lib\site-packages\flask_wtf\csrf.py", line 139, in generate_csrf_token
    return generate_csrf(
  File "C:\Users\mrend\Desktop\mysite\venv\lib\site-packages\flask_wtf\csrf.py", line 46, in generate_csrf
    session[field_name] = hashlib.sha1(os.urandom(64)).hexdigest()
  File "C:\Users\mrend\Desktop\mysite\venv\lib\site-packages\werkzeug\local.py", line 350, in __setitem__
    self._get_current_object()[key] = value
  File "C:\Users\mrend\Desktop\mysite\venv\lib\site-packages\flask\sessions.py", line 102, in _fail
    raise RuntimeError(
RuntimeError: The session is unavailable because no secret key was set.  Set the secret_key on the application to something unique and secret.
Exception on / [GET]
Traceback (most recent call last):
  File "C:\Users\mrend\Desktop\mysite\venv\lib\site-packages\flask\app.py", line 2446, in wsgi_app
    response = self.full_dispatch_request()
  File "C:\Users\mrend\Desktop\mysite\venv\lib\site-packages\flask\app.py", line 1951, in full_dispatch_request
    rv = self.handle_user_exception(e)
  File "C:\Users\mrend\Desktop\mysite\venv\lib\site-packages\flask\app.py", line 1820, in handle_user_exception
    reraise(exc_type, exc_value, tb)
  File "C:\Users\mrend\Desktop\mysite\venv\lib\site-packages\flask\_compat.py", line 39, in reraise
    raise value
  File "C:\Users\mrend\Desktop\mysite\venv\lib\site-packages\flask\app.py", line 1949, in full_dispatch_request
    rv = self.dispatch_request()
  File "C:\Users\mrend\Desktop\mysite\venv\lib\site-packages\flask\app.py", line 1935, in dispatch_request
    return self.view_functions[rule.endpoint](**req.view_args)
  File "C:\Users\mrend\Desktop\mysite\app\routes\index.py", line 26, in index
    return render_template('index.html', posts=posts, comments=comments, likes=likes, form=form, users=users)
NameError: name 'users' is not defined
Exception on / [GET]
Traceback (most recent call last):
  File "C:\Users\mrend\Desktop\mysite\venv\lib\site-packages\flask\app.py", line 2446, in wsgi_app
    response = self.full_dispatch_request()
  File "C:\Users\mrend\Desktop\mysite\venv\lib\site-packages\flask\app.py", line 1951, in full_dispatch_request
    rv = self.handle_user_exception(e)
  File "C:\Users\mrend\Desktop\mysite\venv\lib\site-packages\flask\app.py", line 1820, in handle_user_exception
    reraise(exc_type, exc_value, tb)
  File "C:\Users\mrend\Desktop\mysite\venv\lib\site-packages\flask\_compat.py", line 39, in reraise
    raise value
  File "C:\Users\mrend\Desktop\mysite\venv\lib\site-packages\flask\app.py", line 1949, in full_dispatch_request
    rv = self.dispatch_request()
  File "C:\Users\mrend\Desktop\mysite\venv\lib\site-packages\flask\app.py", line 1935, in dispatch_request
    return self.view_functions[rule.endpoint](**req.view_args)
  File "C:\Users\mrend\Desktop\mysite\app\routes\index.py", line 26, in index
    return render_template('index.html', posts=posts, comments=comments, likes=likes, form=form, users=users)
NameError: name 'users' is not defined
Exception on / [GET]
Traceback (most recent call last):
  File "C:\Users\mrend\Desktop\mysite\venv\lib\site-packages\flask\app.py", line 2446, in wsgi_app
    response = self.full_dispatch_request()
  File "C:\Users\mrend\Desktop\mysite\venv\lib\site-packages\flask\app.py", line 1951, in full_dispatch_request
    rv = self.handle_user_exception(e)
  File "C:\Users\mrend\Desktop\mysite\venv\lib\site-packages\flask\app.py", line 1820, in handle_user_exception
    reraise(exc_type, exc_value, tb)
  File "C:\Users\mrend\Desktop\mysite\venv\lib\site-packages\flask\_compat.py", line 39, in reraise
    raise value
  File "C:\Users\mrend\Desktop\mysite\venv\lib\site-packages\flask\app.py", line 1949, in full_dispatch_request
    rv = self.dispatch_request()
  File "C:\Users\mrend\Desktop\mysite\venv\lib\site-packages\flask\app.py", line 1935, in dispatch_request
    return self.view_functions[rule.endpoint](**req.view_args)
  File "C:\Users\mrend\Desktop\mysite\app\routes\index.py", line 14, in index
    posts, comments, likes = getPosts(cur, '', '', 'id')
  File "C:\Users\mrend\Desktop\mysite\app\utils\functions.py", line 12, in getPosts
    cur.execute(f"SELECT * FROM wpisy WHERE id=%s ORDER BY `{groupby}` DESC",int())
  File "C:\Users\mrend\Desktop\mysite\venv\lib\site-packages\MySQLdb\cursors.py", line 202, in execute
    args = tuple(map(db.literal, args))
TypeError: 'int' object is not iterable
Exception on / [GET]
Traceback (most recent call last):
  File "C:\Users\mrend\Desktop\mysite\venv\lib\site-packages\flask\app.py", line 2446, in wsgi_app
    response = self.full_dispatch_request()
  File "C:\Users\mrend\Desktop\mysite\venv\lib\site-packages\flask\app.py", line 1951, in full_dispatch_request
    rv = self.handle_user_exception(e)
  File "C:\Users\mrend\Desktop\mysite\venv\lib\site-packages\flask\app.py", line 1820, in handle_user_exception
    reraise(exc_type, exc_value, tb)
  File "C:\Users\mrend\Desktop\mysite\venv\lib\site-packages\flask\_compat.py", line 39, in reraise
    raise value
  File "C:\Users\mrend\Desktop\mysite\venv\lib\site-packages\flask\app.py", line 1949, in full_dispatch_request
    rv = self.dispatch_request()
  File "C:\Users\mrend\Desktop\mysite\venv\lib\site-packages\flask\app.py", line 1935, in dispatch_request
    return self.view_functions[rule.endpoint](**req.view_args)
  File "C:\Users\mrend\Desktop\mysite\app\routes\index.py", line 14, in index
    posts, comments, likes = getPosts(cur, '', '', 'id')
  File "C:\Users\mrend\Desktop\mysite\app\utils\functions.py", line 12, in getPosts
    cur.execute(f"SELECT * FROM wpisy WHERE id=%s ORDER BY `{groupby}` DESC",int())
  File "C:\Users\mrend\Desktop\mysite\venv\lib\site-packages\MySQLdb\cursors.py", line 202, in execute
    args = tuple(map(db.literal, args))
TypeError: 'int' object is not iterable
Exception on / [GET]
Traceback (most recent call last):
  File "C:\Users\mrend\Desktop\mysite\venv\lib\site-packages\MySQLdb\cursors.py", line 204, in execute
    query = query % args
TypeError: not enough arguments for format string

During handling of the above exception, another exception occurred:

Traceback (most recent call last):
  File "C:\Users\mrend\Desktop\mysite\venv\lib\site-packages\flask\app.py", line 2446, in wsgi_app
    response = self.full_dispatch_request()
  File "C:\Users\mrend\Desktop\mysite\venv\lib\site-packages\flask\app.py", line 1951, in full_dispatch_request
    rv = self.handle_user_exception(e)
  File "C:\Users\mrend\Desktop\mysite\venv\lib\site-packages\flask\app.py", line 1820, in handle_user_exception
    reraise(exc_type, exc_value, tb)
  File "C:\Users\mrend\Desktop\mysite\venv\lib\site-packages\flask\_compat.py", line 39, in reraise
    raise value
  File "C:\Users\mrend\Desktop\mysite\venv\lib\site-packages\flask\app.py", line 1949, in full_dispatch_request
    rv = self.dispatch_request()
  File "C:\Users\mrend\Desktop\mysite\venv\lib\site-packages\flask\app.py", line 1935, in dispatch_request
    return self.view_functions[rule.endpoint](**req.view_args)
  File "C:\Users\mrend\Desktop\mysite\app\routes\index.py", line 14, in index
    posts, comments, likes = getPosts(cur, '', '', 'id')
  File "C:\Users\mrend\Desktop\mysite\app\utils\functions.py", line 12, in getPosts
    cur.execute(f"SELECT * FROM wpisy WHERE id=%s ORDER BY `{groupby}` DESC",'')
  File "C:\Users\mrend\Desktop\mysite\venv\lib\site-packages\MySQLdb\cursors.py", line 206, in execute
    raise ProgrammingError(str(m))
MySQLdb._exceptions.ProgrammingError: not enough arguments for format string
Exception on / [GET]
Traceback (most recent call last):
  File "C:\Users\mrend\Desktop\mysite\venv\lib\site-packages\MySQLdb\cursors.py", line 204, in execute
    query = query % args
TypeError: not enough arguments for format string

During handling of the above exception, another exception occurred:

Traceback (most recent call last):
  File "C:\Users\mrend\Desktop\mysite\venv\lib\site-packages\flask\app.py", line 2446, in wsgi_app
    response = self.full_dispatch_request()
  File "C:\Users\mrend\Desktop\mysite\venv\lib\site-packages\flask\app.py", line 1951, in full_dispatch_request
    rv = self.handle_user_exception(e)
  File "C:\Users\mrend\Desktop\mysite\venv\lib\site-packages\flask\app.py", line 1820, in handle_user_exception
    reraise(exc_type, exc_value, tb)
  File "C:\Users\mrend\Desktop\mysite\venv\lib\site-packages\flask\_compat.py", line 39, in reraise
    raise value
  File "C:\Users\mrend\Desktop\mysite\venv\lib\site-packages\flask\app.py", line 1949, in full_dispatch_request
    rv = self.dispatch_request()
  File "C:\Users\mrend\Desktop\mysite\venv\lib\site-packages\flask\app.py", line 1935, in dispatch_request
    return self.view_functions[rule.endpoint](**req.view_args)
  File "C:\Users\mrend\Desktop\mysite\app\routes\index.py", line 14, in index
    posts, comments, likes = getPosts(cur, '', '', 'id')
  File "C:\Users\mrend\Desktop\mysite\app\utils\functions.py", line 12, in getPosts
    cur.execute(f"SELECT * FROM wpisy WHERE id=%s ORDER BY `{groupby}` DESC",'')
  File "C:\Users\mrend\Desktop\mysite\venv\lib\site-packages\MySQLdb\cursors.py", line 206, in execute
    raise ProgrammingError(str(m))
MySQLdb._exceptions.ProgrammingError: not enough arguments for format string
Exception on / [GET]
Traceback (most recent call last):
  File "C:\Users\mrend\Desktop\mysite\venv\lib\site-packages\flask\app.py", line 2446, in wsgi_app
    response = self.full_dispatch_request()
  File "C:\Users\mrend\Desktop\mysite\venv\lib\site-packages\flask\app.py", line 1951, in full_dispatch_request
    rv = self.handle_user_exception(e)
  File "C:\Users\mrend\Desktop\mysite\venv\lib\site-packages\flask\app.py", line 1820, in handle_user_exception
    reraise(exc_type, exc_value, tb)
  File "C:\Users\mrend\Desktop\mysite\venv\lib\site-packages\flask\_compat.py", line 39, in reraise
    raise value
  File "C:\Users\mrend\Desktop\mysite\venv\lib\site-packages\flask\app.py", line 1949, in full_dispatch_request
    rv = self.dispatch_request()
  File "C:\Users\mrend\Desktop\mysite\venv\lib\site-packages\flask\app.py", line 1935, in dispatch_request
    return self.view_functions[rule.endpoint](**req.view_args)
  File "C:\Users\mrend\Desktop\mysite\app\routes\index.py", line 14, in index
    posts, comments, likes = getPosts(cur, '', '', 'id')
  File "C:\Users\mrend\Desktop\mysite\app\utils\functions.py", line 12, in getPosts
    cur.execute(f"SELECT * FROM wpisy WHERE id=%s ORDER BY `{groupby}` DESC",2)
  File "C:\Users\mrend\Desktop\mysite\venv\lib\site-packages\MySQLdb\cursors.py", line 202, in execute
    args = tuple(map(db.literal, args))
TypeError: 'int' object is not iterable
Exception on / [GET]
Traceback (most recent call last):
  File "C:\Users\mrend\Desktop\mysite\venv\lib\site-packages\flask\app.py", line 2446, in wsgi_app
    response = self.full_dispatch_request()
  File "C:\Users\mrend\Desktop\mysite\venv\lib\site-packages\flask\app.py", line 1951, in full_dispatch_request
    rv = self.handle_user_exception(e)
  File "C:\Users\mrend\Desktop\mysite\venv\lib\site-packages\flask\app.py", line 1820, in handle_user_exception
    reraise(exc_type, exc_value, tb)
  File "C:\Users\mrend\Desktop\mysite\venv\lib\site-packages\flask\_compat.py", line 39, in reraise
    raise value
  File "C:\Users\mrend\Desktop\mysite\venv\lib\site-packages\flask\app.py", line 1949, in full_dispatch_request
    rv = self.dispatch_request()
  File "C:\Users\mrend\Desktop\mysite\venv\lib\site-packages\flask\app.py", line 1935, in dispatch_request
    return self.view_functions[rule.endpoint](**req.view_args)
  File "C:\Users\mrend\Desktop\mysite\app\routes\index.py", line 14, in index
    posts, comments, likes = getPosts(cur, '', '', 'id')
  File "C:\Users\mrend\Desktop\mysite\app\utils\functions.py", line 12, in getPosts
    cur.execute(f"SELECT * FROM wpisy WHERE id=%s ORDER BY `{groupby}` DESC",2)
  File "C:\Users\mrend\Desktop\mysite\venv\lib\site-packages\MySQLdb\cursors.py", line 202, in execute
    args = tuple(map(db.literal, args))
TypeError: 'int' object is not iterable
Exception on / [GET]
Traceback (most recent call last):
  File "C:\Users\mrend\Desktop\mysite\venv\lib\site-packages\flask\app.py", line 2446, in wsgi_app
    response = self.full_dispatch_request()
  File "C:\Users\mrend\Desktop\mysite\venv\lib\site-packages\flask\app.py", line 1951, in full_dispatch_request
    rv = self.handle_user_exception(e)
  File "C:\Users\mrend\Desktop\mysite\venv\lib\site-packages\flask\app.py", line 1820, in handle_user_exception
    reraise(exc_type, exc_value, tb)
  File "C:\Users\mrend\Desktop\mysite\venv\lib\site-packages\flask\_compat.py", line 39, in reraise
    raise value
  File "C:\Users\mrend\Desktop\mysite\venv\lib\site-packages\flask\app.py", line 1949, in full_dispatch_request
    rv = self.dispatch_request()
  File "C:\Users\mrend\Desktop\mysite\venv\lib\site-packages\flask\app.py", line 1935, in dispatch_request
    return self.view_functions[rule.endpoint](**req.view_args)
  File "C:\Users\mrend\Desktop\mysite\app\routes\index.py", line 14, in index
    posts, comments, likes = getPosts(cur, '', '', 'id')
  File "C:\Users\mrend\Desktop\mysite\app\utils\functions.py", line 12, in getPosts
    cur.execute(f"SELECT * FROM wpisy WHERE id=%s ORDER BY `{groupby}` DESC",346)
  File "C:\Users\mrend\Desktop\mysite\venv\lib\site-packages\MySQLdb\cursors.py", line 202, in execute
    args = tuple(map(db.literal, args))
TypeError: 'int' object is not iterable
Exception on / [GET]
Traceback (most recent call last):
  File "C:\Users\mrend\Desktop\mysite\venv\lib\site-packages\flask\app.py", line 2446, in wsgi_app
    response = self.full_dispatch_request()
  File "C:\Users\mrend\Desktop\mysite\venv\lib\site-packages\flask\app.py", line 1951, in full_dispatch_request
    rv = self.handle_user_exception(e)
  File "C:\Users\mrend\Desktop\mysite\venv\lib\site-packages\flask\app.py", line 1820, in handle_user_exception
    reraise(exc_type, exc_value, tb)
  File "C:\Users\mrend\Desktop\mysite\venv\lib\site-packages\flask\_compat.py", line 39, in reraise
    raise value
  File "C:\Users\mrend\Desktop\mysite\venv\lib\site-packages\flask\app.py", line 1949, in full_dispatch_request
    rv = self.dispatch_request()
  File "C:\Users\mrend\Desktop\mysite\venv\lib\site-packages\flask\app.py", line 1935, in dispatch_request
    return self.view_functions[rule.endpoint](**req.view_args)
  File "C:\Users\mrend\Desktop\mysite\app\routes\index.py", line 14, in index
    posts, comments, likes = getPosts(cur, '', '', 'id')
  File "C:\Users\mrend\Desktop\mysite\app\utils\functions.py", line 12, in getPosts
    cur.execute(f"SELECT * FROM wpisy WHERE id=%s ORDER BY `{groupby}` DESC",346)
  File "C:\Users\mrend\Desktop\mysite\venv\lib\site-packages\MySQLdb\cursors.py", line 202, in execute
    args = tuple(map(db.literal, args))
TypeError: 'int' object is not iterable
Exception on / [GET]
Traceback (most recent call last):
  File "C:\Users\mrend\Desktop\mysite\venv\lib\site-packages\flask\app.py", line 2446, in wsgi_app
    response = self.full_dispatch_request()
  File "C:\Users\mrend\Desktop\mysite\venv\lib\site-packages\flask\app.py", line 1951, in full_dispatch_request
    rv = self.handle_user_exception(e)
  File "C:\Users\mrend\Desktop\mysite\venv\lib\site-packages\flask\app.py", line 1820, in handle_user_exception
    reraise(exc_type, exc_value, tb)
  File "C:\Users\mrend\Desktop\mysite\venv\lib\site-packages\flask\_compat.py", line 39, in reraise
    raise value
  File "C:\Users\mrend\Desktop\mysite\venv\lib\site-packages\flask\app.py", line 1949, in full_dispatch_request
    rv = self.dispatch_request()
  File "C:\Users\mrend\Desktop\mysite\venv\lib\site-packages\flask\app.py", line 1935, in dispatch_request
    return self.view_functions[rule.endpoint](**req.view_args)
  File "C:\Users\mrend\Desktop\mysite\app\routes\index.py", line 14, in index
    posts, comments, likes = getPosts(cur, '', '', 'id')
TypeError: getPosts() takes 3 positional arguments but 4 were given
Exception on / [GET]
Traceback (most recent call last):
  File "C:\Users\mrend\Desktop\mysite\venv\lib\site-packages\flask\app.py", line 2446, in wsgi_app
    response = self.full_dispatch_request()
  File "C:\Users\mrend\Desktop\mysite\venv\lib\site-packages\flask\app.py", line 1951, in full_dispatch_request
    rv = self.handle_user_exception(e)
  File "C:\Users\mrend\Desktop\mysite\venv\lib\site-packages\flask\app.py", line 1820, in handle_user_exception
    reraise(exc_type, exc_value, tb)
  File "C:\Users\mrend\Desktop\mysite\venv\lib\site-packages\flask\_compat.py", line 39, in reraise
    raise value
  File "C:\Users\mrend\Desktop\mysite\venv\lib\site-packages\flask\app.py", line 1949, in full_dispatch_request
    rv = self.dispatch_request()
  File "C:\Users\mrend\Desktop\mysite\venv\lib\site-packages\flask\app.py", line 1935, in dispatch_request
    return self.view_functions[rule.endpoint](**req.view_args)
  File "C:\Users\mrend\Desktop\mysite\app\routes\index.py", line 14, in index
    posts, comments, likes = getPosts(cur, '', '', 'id')
TypeError: getPosts() takes 3 positional arguments but 4 were given
Exception on / [GET]
Traceback (most recent call last):
  File "C:\Users\mrend\Desktop\mysite\venv\lib\site-packages\flask\app.py", line 2446, in wsgi_app
    response = self.full_dispatch_request()
  File "C:\Users\mrend\Desktop\mysite\venv\lib\site-packages\flask\app.py", line 1951, in full_dispatch_request
    rv = self.handle_user_exception(e)
  File "C:\Users\mrend\Desktop\mysite\venv\lib\site-packages\flask\app.py", line 1820, in handle_user_exception
    reraise(exc_type, exc_value, tb)
  File "C:\Users\mrend\Desktop\mysite\venv\lib\site-packages\flask\_compat.py", line 39, in reraise
    raise value
  File "C:\Users\mrend\Desktop\mysite\venv\lib\site-packages\flask\app.py", line 1949, in full_dispatch_request
    rv = self.dispatch_request()
  File "C:\Users\mrend\Desktop\mysite\venv\lib\site-packages\flask\app.py", line 1935, in dispatch_request
    return self.view_functions[rule.endpoint](**req.view_args)
  File "C:\Users\mrend\Desktop\mysite\app\routes\index.py", line 14, in index
    posts, comments, likes = getPosts(cur, '', 'id')
  File "C:\Users\mrend\Desktop\mysite\app\utils\functions.py", line 16, in getPosts
    cur.execute("SELECT * FROM likes {where}")
  File "C:\Users\mrend\Desktop\mysite\venv\lib\site-packages\MySQLdb\cursors.py", line 209, in execute
    res = self._query(query)
  File "C:\Users\mrend\Desktop\mysite\venv\lib\site-packages\MySQLdb\cursors.py", line 315, in _query
    db.query(q)
  File "C:\Users\mrend\Desktop\mysite\venv\lib\site-packages\MySQLdb\connections.py", line 239, in query
    _mysql.connection.query(self, query)
MySQLdb._exceptions.ProgrammingError: (1064, "You have an error in your SQL syntax; check the manual that corresponds to your MariaDB server version for the right syntax to use near '{where}' at line 1")
Exception on / [GET]
Traceback (most recent call last):
  File "C:\Users\mrend\Desktop\mysite\venv\lib\site-packages\flask\app.py", line 2446, in wsgi_app
    response = self.full_dispatch_request()
  File "C:\Users\mrend\Desktop\mysite\venv\lib\site-packages\flask\app.py", line 1951, in full_dispatch_request
    rv = self.handle_user_exception(e)
  File "C:\Users\mrend\Desktop\mysite\venv\lib\site-packages\flask\app.py", line 1820, in handle_user_exception
    reraise(exc_type, exc_value, tb)
  File "C:\Users\mrend\Desktop\mysite\venv\lib\site-packages\flask\_compat.py", line 39, in reraise
    raise value
  File "C:\Users\mrend\Desktop\mysite\venv\lib\site-packages\flask\app.py", line 1949, in full_dispatch_request
    rv = self.dispatch_request()
  File "C:\Users\mrend\Desktop\mysite\venv\lib\site-packages\flask\app.py", line 1935, in dispatch_request
    return self.view_functions[rule.endpoint](**req.view_args)
  File "C:\Users\mrend\Desktop\mysite\app\routes\index.py", line 14, in index
    posts, comments, likes = getPosts(cur, '', 'id')
  File "C:\Users\mrend\Desktop\mysite\app\utils\functions.py", line 16, in getPosts
    cur.execute("SELECT * FROM likes {where}")
  File "C:\Users\mrend\Desktop\mysite\venv\lib\site-packages\MySQLdb\cursors.py", line 209, in execute
    res = self._query(query)
  File "C:\Users\mrend\Desktop\mysite\venv\lib\site-packages\MySQLdb\cursors.py", line 315, in _query
    db.query(q)
  File "C:\Users\mrend\Desktop\mysite\venv\lib\site-packages\MySQLdb\connections.py", line 239, in query
    _mysql.connection.query(self, query)
MySQLdb._exceptions.ProgrammingError: (1064, "You have an error in your SQL syntax; check the manual that corresponds to your MariaDB server version for the right syntax to use near '{where}' at line 1")
Exception on /profil/ivall [GET]
Traceback (most recent call last):
  File "C:\Users\mrend\Desktop\mysite\venv\lib\site-packages\flask\app.py", line 2446, in wsgi_app
    response = self.full_dispatch_request()
  File "C:\Users\mrend\Desktop\mysite\venv\lib\site-packages\flask\app.py", line 1951, in full_dispatch_request
    rv = self.handle_user_exception(e)
  File "C:\Users\mrend\Desktop\mysite\venv\lib\site-packages\flask\app.py", line 1820, in handle_user_exception
    reraise(exc_type, exc_value, tb)
  File "C:\Users\mrend\Desktop\mysite\venv\lib\site-packages\flask\_compat.py", line 39, in reraise
    raise value
  File "C:\Users\mrend\Desktop\mysite\venv\lib\site-packages\flask\app.py", line 1949, in full_dispatch_request
    rv = self.dispatch_request()
  File "C:\Users\mrend\Desktop\mysite\venv\lib\site-packages\flask\app.py", line 1935, in dispatch_request
    return self.view_functions[rule.endpoint](**req.view_args)
  File "C:\Users\mrend\Desktop\mysite\app\routes\user_profile.py", line 15, in profil
    posts, comments, likes = getPosts(cur, f'WHERE autor={nick}', 'id')
  File "C:\Users\mrend\Desktop\mysite\app\utils\functions.py", line 12, in getPosts
    cur.execute(f"SELECT * FROM wpisy {where} ORDER BY `{order_by}` DESC")
  File "C:\Users\mrend\Desktop\mysite\venv\lib\site-packages\MySQLdb\cursors.py", line 209, in execute
    res = self._query(query)
  File "C:\Users\mrend\Desktop\mysite\venv\lib\site-packages\MySQLdb\cursors.py", line 315, in _query
    db.query(q)
  File "C:\Users\mrend\Desktop\mysite\venv\lib\site-packages\MySQLdb\connections.py", line 239, in query
    _mysql.connection.query(self, query)
MySQLdb._exceptions.OperationalError: (1054, "Unknown column 'ivall' in 'where clause'")
Exception on /profil/ivall [GET]
Traceback (most recent call last):
  File "C:\Users\mrend\Desktop\mysite\venv\lib\site-packages\flask\app.py", line 2446, in wsgi_app
    response = self.full_dispatch_request()
  File "C:\Users\mrend\Desktop\mysite\venv\lib\site-packages\flask\app.py", line 1951, in full_dispatch_request
    rv = self.handle_user_exception(e)
  File "C:\Users\mrend\Desktop\mysite\venv\lib\site-packages\flask\app.py", line 1820, in handle_user_exception
    reraise(exc_type, exc_value, tb)
  File "C:\Users\mrend\Desktop\mysite\venv\lib\site-packages\flask\_compat.py", line 39, in reraise
    raise value
  File "C:\Users\mrend\Desktop\mysite\venv\lib\site-packages\flask\app.py", line 1949, in full_dispatch_request
    rv = self.dispatch_request()
  File "C:\Users\mrend\Desktop\mysite\venv\lib\site-packages\flask\app.py", line 1935, in dispatch_request
    return self.view_functions[rule.endpoint](**req.view_args)
  File "C:\Users\mrend\Desktop\mysite\app\routes\user_profile.py", line 15, in profil
    posts, comments, likes = getPosts(cur, f'WHERE autor="{nick}"', 'id')
  File "C:\Users\mrend\Desktop\mysite\app\utils\functions.py", line 16, in getPosts
    cur.execute(f"SELECT * FROM likes {where}")
  File "C:\Users\mrend\Desktop\mysite\venv\lib\site-packages\MySQLdb\cursors.py", line 209, in execute
    res = self._query(query)
  File "C:\Users\mrend\Desktop\mysite\venv\lib\site-packages\MySQLdb\cursors.py", line 315, in _query
    db.query(q)
  File "C:\Users\mrend\Desktop\mysite\venv\lib\site-packages\MySQLdb\connections.py", line 239, in query
    _mysql.connection.query(self, query)
MySQLdb._exceptions.OperationalError: (1054, "Unknown column 'autor' in 'where clause'")
Exception on /profil/ivall [GET]
Traceback (most recent call last):
  File "C:\Users\mrend\Desktop\mysite\venv\lib\site-packages\flask\app.py", line 2446, in wsgi_app
    response = self.full_dispatch_request()
  File "C:\Users\mrend\Desktop\mysite\venv\lib\site-packages\flask\app.py", line 1951, in full_dispatch_request
    rv = self.handle_user_exception(e)
  File "C:\Users\mrend\Desktop\mysite\venv\lib\site-packages\flask\app.py", line 1820, in handle_user_exception
    reraise(exc_type, exc_value, tb)
  File "C:\Users\mrend\Desktop\mysite\venv\lib\site-packages\flask\_compat.py", line 39, in reraise
    raise value
  File "C:\Users\mrend\Desktop\mysite\venv\lib\site-packages\flask\app.py", line 1949, in full_dispatch_request
    rv = self.dispatch_request()
  File "C:\Users\mrend\Desktop\mysite\venv\lib\site-packages\flask\app.py", line 1935, in dispatch_request
    return self.view_functions[rule.endpoint](**req.view_args)
  File "C:\Users\mrend\Desktop\mysite\app\routes\user_profile.py", line 15, in profil
    posts, comments, likes = getPosts(cur, f'WHERE autor=\'{nick}\'', 'id')
  File "C:\Users\mrend\Desktop\mysite\app\utils\functions.py", line 16, in getPosts
    cur.execute(f"SELECT * FROM likes {where}")
  File "C:\Users\mrend\Desktop\mysite\venv\lib\site-packages\MySQLdb\cursors.py", line 209, in execute
    res = self._query(query)
  File "C:\Users\mrend\Desktop\mysite\venv\lib\site-packages\MySQLdb\cursors.py", line 315, in _query
    db.query(q)
  File "C:\Users\mrend\Desktop\mysite\venv\lib\site-packages\MySQLdb\connections.py", line 239, in query
    _mysql.connection.query(self, query)
MySQLdb._exceptions.OperationalError: (1054, "Unknown column 'autor' in 'where clause'")
Exception on /profil/ivall [GET]
Traceback (most recent call last):
  File "C:\Users\mrend\Desktop\mysite\venv\lib\site-packages\flask\app.py", line 2446, in wsgi_app
    response = self.full_dispatch_request()
  File "C:\Users\mrend\Desktop\mysite\venv\lib\site-packages\flask\app.py", line 1951, in full_dispatch_request
    rv = self.handle_user_exception(e)
  File "C:\Users\mrend\Desktop\mysite\venv\lib\site-packages\flask\app.py", line 1820, in handle_user_exception
    reraise(exc_type, exc_value, tb)
  File "C:\Users\mrend\Desktop\mysite\venv\lib\site-packages\flask\_compat.py", line 39, in reraise
    raise value
  File "C:\Users\mrend\Desktop\mysite\venv\lib\site-packages\flask\app.py", line 1949, in full_dispatch_request
    rv = self.dispatch_request()
  File "C:\Users\mrend\Desktop\mysite\venv\lib\site-packages\flask\app.py", line 1935, in dispatch_request
    return self.view_functions[rule.endpoint](**req.view_args)
  File "C:\Users\mrend\Desktop\mysite\app\routes\user_profile.py", line 15, in profil
    posts, comments, likes = getPosts(cur, f'WHERE autor=ivall', 'id')
  File "C:\Users\mrend\Desktop\mysite\app\utils\functions.py", line 12, in getPosts
    cur.execute(f"SELECT * FROM wpisy {where} ORDER BY `{order_by}` DESC")
  File "C:\Users\mrend\Desktop\mysite\venv\lib\site-packages\MySQLdb\cursors.py", line 209, in execute
    res = self._query(query)
  File "C:\Users\mrend\Desktop\mysite\venv\lib\site-packages\MySQLdb\cursors.py", line 315, in _query
    db.query(q)
  File "C:\Users\mrend\Desktop\mysite\venv\lib\site-packages\MySQLdb\connections.py", line 239, in query
    _mysql.connection.query(self, query)
MySQLdb._exceptions.OperationalError: (1054, "Unknown column 'ivall' in 'where clause'")
Exception on /profil/ivall [GET]
Traceback (most recent call last):
  File "C:\Users\mrend\Desktop\mysite\venv\lib\site-packages\flask\app.py", line 2446, in wsgi_app
    response = self.full_dispatch_request()
  File "C:\Users\mrend\Desktop\mysite\venv\lib\site-packages\flask\app.py", line 1951, in full_dispatch_request
    rv = self.handle_user_exception(e)
  File "C:\Users\mrend\Desktop\mysite\venv\lib\site-packages\flask\app.py", line 1820, in handle_user_exception
    reraise(exc_type, exc_value, tb)
  File "C:\Users\mrend\Desktop\mysite\venv\lib\site-packages\flask\_compat.py", line 39, in reraise
    raise value
  File "C:\Users\mrend\Desktop\mysite\venv\lib\site-packages\flask\app.py", line 1949, in full_dispatch_request
    rv = self.dispatch_request()
  File "C:\Users\mrend\Desktop\mysite\venv\lib\site-packages\flask\app.py", line 1935, in dispatch_request
    return self.view_functions[rule.endpoint](**req.view_args)
  File "C:\Users\mrend\Desktop\mysite\app\routes\user_profile.py", line 15, in profil
    posts, comments, likes = getPosts(cur, f"WHERE autor='ivall'", 'id')
  File "C:\Users\mrend\Desktop\mysite\app\utils\functions.py", line 16, in getPosts
    cur.execute(f"SELECT * FROM likes {where}")
  File "C:\Users\mrend\Desktop\mysite\venv\lib\site-packages\MySQLdb\cursors.py", line 209, in execute
    res = self._query(query)
  File "C:\Users\mrend\Desktop\mysite\venv\lib\site-packages\MySQLdb\cursors.py", line 315, in _query
    db.query(q)
  File "C:\Users\mrend\Desktop\mysite\venv\lib\site-packages\MySQLdb\connections.py", line 239, in query
    _mysql.connection.query(self, query)
MySQLdb._exceptions.OperationalError: (1054, "Unknown column 'autor' in 'where clause'")
Exception on / [GET]
Traceback (most recent call last):
  File "C:\Users\mrend\Desktop\mysite\venv\lib\site-packages\flask\app.py", line 2446, in wsgi_app
    response = self.full_dispatch_request()
  File "C:\Users\mrend\Desktop\mysite\venv\lib\site-packages\flask\app.py", line 1951, in full_dispatch_request
    rv = self.handle_user_exception(e)
  File "C:\Users\mrend\Desktop\mysite\venv\lib\site-packages\flask\app.py", line 1820, in handle_user_exception
    reraise(exc_type, exc_value, tb)
  File "C:\Users\mrend\Desktop\mysite\venv\lib\site-packages\flask\_compat.py", line 39, in reraise
    raise value
  File "C:\Users\mrend\Desktop\mysite\venv\lib\site-packages\flask\app.py", line 1949, in full_dispatch_request
    rv = self.dispatch_request()
  File "C:\Users\mrend\Desktop\mysite\venv\lib\site-packages\flask\app.py", line 1935, in dispatch_request
    return self.view_functions[rule.endpoint](**req.view_args)
  File "C:\Users\mrend\Desktop\mysite\app\routes\index.py", line 14, in index
    posts, comments, likes = getPosts(cur, '', 'id', '')
TypeError: getPosts() takes 3 positional arguments but 4 were given
Exception on / [GET]
Traceback (most recent call last):
  File "C:\Users\mrend\Desktop\mysite\venv\lib\site-packages\flask\app.py", line 2446, in wsgi_app
    response = self.full_dispatch_request()
  File "C:\Users\mrend\Desktop\mysite\venv\lib\site-packages\flask\app.py", line 1951, in full_dispatch_request
    rv = self.handle_user_exception(e)
  File "C:\Users\mrend\Desktop\mysite\venv\lib\site-packages\flask\app.py", line 1820, in handle_user_exception
    reraise(exc_type, exc_value, tb)
  File "C:\Users\mrend\Desktop\mysite\venv\lib\site-packages\flask\_compat.py", line 39, in reraise
    raise value
  File "C:\Users\mrend\Desktop\mysite\venv\lib\site-packages\flask\app.py", line 1949, in full_dispatch_request
    rv = self.dispatch_request()
  File "C:\Users\mrend\Desktop\mysite\venv\lib\site-packages\flask\app.py", line 1935, in dispatch_request
    return self.view_functions[rule.endpoint](**req.view_args)
  File "C:\Users\mrend\Desktop\mysite\app\routes\index.py", line 14, in index
    posts, comments, likes = getPosts(cur, '', 'id', '')
TypeError: getPosts() takes 3 positional arguments but 4 were given
Exception on /wpis/346 [GET]
Traceback (most recent call last):
  File "C:\Users\mrend\Desktop\mysite\venv\lib\site-packages\flask\app.py", line 2446, in wsgi_app
    response = self.full_dispatch_request()
  File "C:\Users\mrend\Desktop\mysite\venv\lib\site-packages\flask\app.py", line 1951, in full_dispatch_request
    rv = self.handle_user_exception(e)
  File "C:\Users\mrend\Desktop\mysite\venv\lib\site-packages\flask\app.py", line 1820, in handle_user_exception
    reraise(exc_type, exc_value, tb)
  File "C:\Users\mrend\Desktop\mysite\venv\lib\site-packages\flask\_compat.py", line 39, in reraise
    raise value
  File "C:\Users\mrend\Desktop\mysite\venv\lib\site-packages\flask\app.py", line 1949, in full_dispatch_request
    rv = self.dispatch_request()
  File "C:\Users\mrend\Desktop\mysite\venv\lib\site-packages\flask\app.py", line 1935, in dispatch_request
    return self.view_functions[rule.endpoint](**req.view_args)
  File "C:\Users\mrend\Desktop\mysite\app\routes\post.py", line 13, in post
    post, comments, likes = getPosts(cur, f'WHERE post_id={postid}', 'id')
  File "C:\Users\mrend\Desktop\mysite\app\utils\functions.py", line 12, in getPosts
    cur.execute(f"SELECT * FROM wpisy {where} ORDER BY `{order_by}` DESC")
  File "C:\Users\mrend\Desktop\mysite\venv\lib\site-packages\MySQLdb\cursors.py", line 209, in execute
    res = self._query(query)
  File "C:\Users\mrend\Desktop\mysite\venv\lib\site-packages\MySQLdb\cursors.py", line 315, in _query
    db.query(q)
  File "C:\Users\mrend\Desktop\mysite\venv\lib\site-packages\MySQLdb\connections.py", line 239, in query
    _mysql.connection.query(self, query)
MySQLdb._exceptions.OperationalError: (1054, "Unknown column 'post_id' in 'where clause'")
Exception on /obserwowane [GET]
Traceback (most recent call last):
  File "C:\Users\mrend\Desktop\mysite\venv\lib\site-packages\flask\app.py", line 2446, in wsgi_app
    response = self.full_dispatch_request()
  File "C:\Users\mrend\Desktop\mysite\venv\lib\site-packages\flask\app.py", line 1951, in full_dispatch_request
    rv = self.handle_user_exception(e)
  File "C:\Users\mrend\Desktop\mysite\venv\lib\site-packages\flask\app.py", line 1820, in handle_user_exception
    reraise(exc_type, exc_value, tb)
  File "C:\Users\mrend\Desktop\mysite\venv\lib\site-packages\flask\_compat.py", line 39, in reraise
    raise value
  File "C:\Users\mrend\Desktop\mysite\venv\lib\site-packages\flask\app.py", line 1949, in full_dispatch_request
    rv = self.dispatch_request()
  File "C:\Users\mrend\Desktop\mysite\venv\lib\site-packages\flask\app.py", line 1935, in dispatch_request
    return self.view_functions[rule.endpoint](**req.view_args)
  File "C:\Users\mrend\Desktop\mysite\app\routes\follows.py", line 26, in follows
    posts, comments, likes = getPosts(cur, f'WHERE post_id IN {id_of_posts}', 'id')
  File "C:\Users\mrend\Desktop\mysite\app\utils\functions.py", line 12, in getPosts
    cur.execute(f"SELECT * FROM wpisy {where.replace('post_id', 'id')} ORDER BY `{order_by}` DESC")
  File "C:\Users\mrend\Desktop\mysite\venv\lib\site-packages\MySQLdb\cursors.py", line 209, in execute
    res = self._query(query)
  File "C:\Users\mrend\Desktop\mysite\venv\lib\site-packages\MySQLdb\cursors.py", line 315, in _query
    db.query(q)
  File "C:\Users\mrend\Desktop\mysite\venv\lib\site-packages\MySQLdb\connections.py", line 239, in query
    _mysql.connection.query(self, query)
MySQLdb._exceptions.ProgrammingError: (1064, "You have an error in your SQL syntax; check the manual that corresponds to your MariaDB server version for the right syntax to use near '[155, 177] ORDER BY `id` DESC' at line 1")
Exception on /obserwowane [GET]
Traceback (most recent call last):
  File "C:\Users\mrend\Desktop\mysite\venv\lib\site-packages\flask\app.py", line 2446, in wsgi_app
    response = self.full_dispatch_request()
  File "C:\Users\mrend\Desktop\mysite\venv\lib\site-packages\flask\app.py", line 1951, in full_dispatch_request
    rv = self.handle_user_exception(e)
  File "C:\Users\mrend\Desktop\mysite\venv\lib\site-packages\flask\app.py", line 1820, in handle_user_exception
    reraise(exc_type, exc_value, tb)
  File "C:\Users\mrend\Desktop\mysite\venv\lib\site-packages\flask\_compat.py", line 39, in reraise
    raise value
  File "C:\Users\mrend\Desktop\mysite\venv\lib\site-packages\flask\app.py", line 1949, in full_dispatch_request
    rv = self.dispatch_request()
  File "C:\Users\mrend\Desktop\mysite\venv\lib\site-packages\flask\app.py", line 1935, in dispatch_request
    return self.view_functions[rule.endpoint](**req.view_args)
  File "C:\Users\mrend\Desktop\mysite\app\routes\follows.py", line 26, in follows
    posts, comments, likes = getPosts(cur, f'WHERE id IN {id_of_posts}', 'id')
  File "C:\Users\mrend\Desktop\mysite\app\utils\functions.py", line 12, in getPosts
    cur.execute(f"SELECT * FROM wpisy {where.replace('post_id', 'id')} ORDER BY `{order_by}` DESC")
  File "C:\Users\mrend\Desktop\mysite\venv\lib\site-packages\MySQLdb\cursors.py", line 209, in execute
    res = self._query(query)
  File "C:\Users\mrend\Desktop\mysite\venv\lib\site-packages\MySQLdb\cursors.py", line 315, in _query
    db.query(q)
  File "C:\Users\mrend\Desktop\mysite\venv\lib\site-packages\MySQLdb\connections.py", line 239, in query
    _mysql.connection.query(self, query)
MySQLdb._exceptions.ProgrammingError: (1064, "You have an error in your SQL syntax; check the manual that corresponds to your MariaDB server version for the right syntax to use near '[155, 177] ORDER BY `id` DESC' at line 1")
